Workbook

Sheet Portfolio Guide
A1: PLAN | KIND INSIGHTS
A4: CO2 Volume Calculator
A7: ENERGY ANALYSIS · PUBLIC COMMUNICATION · APPLIED MODELING
A9: PURPOSE | B9: PURPOSE | C9: Translates electricity-related carbon emissions into an estimated physical volume of CO2e using documented assumptions and source data. | D9: Translates electricity-related carbon emissions into an estimated physical volume of CO2e using documented assumptions and source data. | E9: Translates electricity-related carbon emissions into an estimated physical volume of CO2e using documented assumptions and source data. | F9: Translates electricity-related carbon emissions into an estimated physical volume of CO2e using documented assumptions and source data. | G9: Translates electricity-related carbon emissions into an estimated physical volume of CO2e using documented assumptions and source data. | H9: Translates electricity-related carbon emissions into an estimated physical volume of CO2e using documented assumptions and source data.
C10: Translates electricity-related carbon emissions into an estimated physical volume of CO2e using documented assumptions and source data. | D10: Translates electricity-related carbon emissions into an estimated physical volume of CO2e using documented assumptions and source data. | E10: Translates electricity-related carbon emissions into an estimated physical volume of CO2e using documented assumptions and source data. | F10: Translates electricity-related carbon emissions into an estimated physical volume of CO2e using documented assumptions and source data. | G10: Translates electricity-related carbon emissions into an estimated physical volume of CO2e using documented assumptions and source data. | H10: Translates electricity-related carbon emissions into an estimated physical volume of CO2e using documented assumptions and source data.
C11: Translates electricity-related carbon emissions into an estimated physical volume of CO2e using documented assumptions and source data. | D11: Translates electricity-related carbon emissions into an estimated physical volume of CO2e using documented assumptions and source data. | E11: Translates electricity-related carbon emissions into an estimated physical volume of CO2e using documented assumptions and source data. | F11: Translates electricity-related carbon emissions into an estimated physical volume of CO2e using documented assumptions and source data. | G11: Translates electricity-related carbon emissions into an estimated physical volume of CO2e using documented assumptions and source data. | H11: Translates electricity-related carbon emissions into an estimated physical volume of CO2e using documented assumptions and source data.
A13: HOW TO USE | B13: HOW TO USE | C13: Begin on the calculator sheet, review the stated assumptions, and change only designated input cells. | D13: Begin on the calculator sheet, review the stated assumptions, and change only designated input cells. | E13: Begin on the calculator sheet, review the stated assumptions, and change only designated input cells. | F13: Begin on the calculator sheet, review the stated assumptions, and change only designated input cells. | G13: Begin on the calculator sheet, review the stated assumptions, and change only designated input cells. | H13: Begin on the calculator sheet, review the stated assumptions, and change only designated input cells.
C14: Begin on the calculator sheet, review the stated assumptions, and change only designated input cells. | D14: Begin on the calculator sheet, review the stated assumptions, and change only designated input cells. | E14: Begin on the calculator sheet, review the stated assumptions, and change only designated input cells. | F14: Begin on the calculator sheet, review the stated assumptions, and change only designated input cells. | G14: Begin on the calculator sheet, review the stated assumptions, and change only designated input cells. | H14: Begin on the calculator sheet, review the stated assumptions, and change only designated input cells.
C15: Begin on the calculator sheet, review the stated assumptions, and change only designated input cells. | D15: Begin on the calculator sheet, review the stated assumptions, and change only designated input cells. | E15: Begin on the calculator sheet, review the stated assumptions, and change only designated input cells. | F15: Begin on the calculator sheet, review the stated assumptions, and change only designated input cells. | G15: Begin on the calculator sheet, review the stated assumptions, and change only designated input cells. | H15: Begin on the calculator sheet, review the stated assumptions, and change only designated input cells.
A17: IMPORTANT | B17: IMPORTANT | C17: Illustrative analytical tool. Results depend on emissions factors, renewable portfolio assumptions, and the stated temperature and pressure. | D17: Illustrative analytical tool. Results depend on emissions factors, renewable portfolio assumptions, and the stated temperature and pressure. | E17: Illustrative analytical tool. Results depend on emissions factors, renewable portfolio assumptions, and the stated temperature and pressure. | F17: Illustrative analytical tool. Results depend on emissions factors, renewable portfolio assumptions, and the stated temperature and pressure. | G17: Illustrative analytical tool. Results depend on emissions factors, renewable portfolio assumptions, and the stated temperature and pressure. | H17: Illustrative analytical tool. Results depend on emissions factors, renewable portfolio assumptions, and the stated temperature and pressure.
C18: Illustrative analytical tool. Results depend on emissions factors, renewable portfolio assumptions, and the stated temperature and pressure. | D18: Illustrative analytical tool. Results depend on emissions factors, renewable portfolio assumptions, and the stated temperature and pressure. | E18: Illustrative analytical tool. Results depend on emissions factors, renewable portfolio assumptions, and the stated temperature and pressure. | F18: Illustrative analytical tool. Results depend on emissions factors, renewable portfolio assumptions, and the stated temperature and pressure. | G18: Illustrative analytical tool. Results depend on emissions factors, renewable portfolio assumptions, and the stated temperature and pressure. | H18: Illustrative analytical tool. Results depend on emissions factors, renewable portfolio assumptions, and the stated temperature and pressure.
C19: Illustrative analytical tool. Results depend on emissions factors, renewable portfolio assumptions, and the stated temperature and pressure. | D19: Illustrative analytical tool. Results depend on emissions factors, renewable portfolio assumptions, and the stated temperature and pressure. | E19: Illustrative analytical tool. Results depend on emissions factors, renewable portfolio assumptions, and the stated temperature and pressure. | F19: Illustrative analytical tool. Results depend on emissions factors, renewable portfolio assumptions, and the stated temperature and pressure. | G19: Illustrative analytical tool. Results depend on emissions factors, renewable portfolio assumptions, and the stated temperature and pressure. | H19: Illustrative analytical tool. Results depend on emissions factors, renewable portfolio assumptions, and the stated temperature and pressure.
C20: Illustrative analytical tool. Results depend on emissions factors, renewable portfolio assumptions, and the stated temperature and pressure. | D20: Illustrative analytical tool. Results depend on emissions factors, renewable portfolio assumptions, and the stated temperature and pressure. | E20: Illustrative analytical tool. Results depend on emissions factors, renewable portfolio assumptions, and the stated temperature and pressure. | F20: Illustrative analytical tool. Results depend on emissions factors, renewable portfolio assumptions, and the stated temperature and pressure. | G20: Illustrative analytical tool. Results depend on emissions factors, renewable portfolio assumptions, and the stated temperature and pressure. | H20: Illustrative analytical tool. Results depend on emissions factors, renewable portfolio assumptions, and the stated temperature and pressure.
A22: PORTFOLIO NOTE | B22: PORTFOLIO NOTE | C22: This workbook is a cleaned presentation copy of prior analytical work. Core calculations and substantive content have not been rewritten. | D22: This workbook is a cleaned presentation copy of prior analytical work. Core calculations and substantive content have not been rewritten. | E22: This workbook is a cleaned presentation copy of prior analytical work. Core calculations and substantive content have not been rewritten. | F22: This workbook is a cleaned presentation copy of prior analytical work. Core calculations and substantive content have not been rewritten. | G22: This workbook is a cleaned presentation copy of prior analytical work. Core calculations and substantive content have not been rewritten. | H22: This workbook is a cleaned presentation copy of prior analytical work. Core calculations and substantive content have not been rewritten.
C23: This workbook is a cleaned presentation copy of prior analytical work. Core calculations and substantive content have not been rewritten. | D23: This workbook is a cleaned presentation copy of prior analytical work. Core calculations and substantive content have not been rewritten. | E23: This workbook is a cleaned presentation copy of prior analytical work. Core calculations and substantive content have not been rewritten. | F23: This workbook is a cleaned presentation copy of prior analytical work. Core calculations and substantive content have not been rewritten. | G23: This workbook is a cleaned presentation copy of prior analytical work. Core calculations and substantive content have not been rewritten. | H23: This workbook is a cleaned presentation copy of prior analytical work. Core calculations and substantive content have not been rewritten.
C24: This workbook is a cleaned presentation copy of prior analytical work. Core calculations and substantive content have not been rewritten. | D24: This workbook is a cleaned presentation copy of prior analytical work. Core calculations and substantive content have not been rewritten. | E24: This workbook is a cleaned presentation copy of prior analytical work. Core calculations and substantive content have not been rewritten. | F24: This workbook is a cleaned presentation copy of prior analytical work. Core calculations and substantive content have not been rewritten. | G24: This workbook is a cleaned presentation copy of prior analytical work. Core calculations and substantive content have not been rewritten. | H24: This workbook is a cleaned presentation copy of prior analytical work. Core calculations and substantive content have not been rewritten.
A26: Grounded in evidence. Focused on impact.

Sheet Volume of CO2e Calculator
A1: RPS Standards & Resulting CO2 Emissions | B1: Daily KWH Usage | C1: Zero-Renewables | D1: 2010 | E1: 2015 | F1: (2021, Base Values) | G1: 2020-2030 | H1: 2030 | I1: 2030-2040 | J1: 2040 | K1: 2040-2045 | L1: 2045
A2: Calculator | C2: The use of these household items would generate CO2 equivalent emissions the of this many Cubic ft
A3: Type KWh HERE: | B3: 16 | C3: {=$B$3*'Daily HH CO2 w RPS'!C5:L5} -> 258.8714 | D3: 232.98426 | E3: 220.04069 | F3: 209.74811 | G3: 181.20998 | H3: 155.32284 | I3: 116.49213 | J3: 77.66142 | K3: 38.83071 | L3: 0
C4: Or a Ball of this many feet in diameter
C5: =$B$3*'Daily HH CO2 w RPS'!C6 -> 50.20827 | D5: =$B$3*'Daily HH CO2 w RPS'!D6 -> 48.475552 | E5: =$B$3*'Daily HH CO2 w RPS'!E6 -> 47.5607 | F5: =$B$3*'Daily HH CO2 w RPS'!F6 -> 46.807264 | G5: =$B$3*'Daily HH CO2 w RPS'!G6 -> 44.580124 | H5: =$B$3*'Daily HH CO2 w RPS'!H6 -> 42.347295 | I5: =$B$3*'Daily HH CO2 w RPS'!I6 -> 38.475071 | J5: =$B$3*'Daily HH CO2 w RPS'!J6 -> 33.611071 | ... L5: =$B$3*'Daily HH CO2 w RPS'!L6 -> 0
A6: Or select an appliance below: | C6: Zero-Renewables | D6: 2010 | E6: 2015 | F6: (2021, Base Values) | G6: 2020-2030 | H6: 2030 | I6: 2030-2040 | J6: 2040 | K6: 2040-2045 | L6: 2045
C7: The use of these household items would generate CO2 equivalent emissions the of this many Cubic ft
A8: TV (3 hr.) | B8: =VLOOKUP(A8,'Daily HH CO2 w RPS'!A9:B23,2,FALSE) -> 0.45 | C8: =$B$8*'Daily HH CO2 w RPS'!C5 -> 7.2807582 | D8: =$B$8*'Daily HH CO2 w RPS'!D5 -> 6.5526824 | E8: =$B$8*'Daily HH CO2 w RPS'!E5 -> 6.1886444 | F8: =$B$8*'Daily HH CO2 w RPS'!F5 -> 5.8991657 | G8: =$B$8*'Daily HH CO2 w RPS'!G5 -> 5.0965307 | H8: =$B$8*'Daily HH CO2 w RPS'!H5 -> 4.3684549 | I8: =$B$8*'Daily HH CO2 w RPS'!I5 -> 3.2763412 | J8: =$B$8*'Daily HH CO2 w RPS'!J5 -> 2.1842275 | ... L8: =$B$8*'Daily HH CO2 w RPS'!L5 -> 0
C9: Or a Ball of this many feet in diameter
C10: =$B$8*'Daily HH CO2 w RPS'!C6 -> 1.4121076 | D10: =$B$8*'Daily HH CO2 w RPS'!D6 -> 1.3633749 | E10: =$B$8*'Daily HH CO2 w RPS'!E6 -> 1.3376447 | F10: =$B$8*'Daily HH CO2 w RPS'!F6 -> 1.3164543 | G10: =$B$8*'Daily HH CO2 w RPS'!G6 -> 1.253816 | H10: =$B$8*'Daily HH CO2 w RPS'!H6 -> 1.1910177 | I10: =$B$8*'Daily HH CO2 w RPS'!I6 -> 1.0821114 | J10: =$B$8*'Daily HH CO2 w RPS'!J6 -> 0.94531136 | ... L10: =$B$8*'Daily HH CO2 w RPS'!L6 -> 0
A14: Vehicle Emissions Per 10 Mile: | B14: KWH/ 10 Mi | C14: Zero-Renewables | D14: 2010 | E14: 2015 | F14: (2021, Base Values) | G14: 2020-2030 | H14: 2030 | I14: 2030-2040 | J14: 2040 | K14: 2040-2045 | L14: 2045
C15: The use of these household items would generate CO2 equivalent emissions the of this many Cubic ft
A16: Electric Vehicles | B16: 2 | C16: 32.358925 | D16: 29.123033 | E16: 27.505086 | F16: 26.218514 | G16: 22.651248 | H16: 19.415355 | I16: 14.561516 | J16: 9.7076776 | K16: 4.8538388 | L16: 0
C17: Or a Ball of this many feet in diameter
C18: 6.2760338 | D18: 6.059444 | E18: 5.9450875 | F18: 5.850908 | G18: 5.5725155 | H18: 5.2934119 | I18: 4.8093839 | J18: 4.2013838 | K18: 3.3346406 | L18: 0
A19: Choose a Vehicle to Compare | C19: Zero-Renewables | D19: 2010 | E19: 2015 | F19: (2021, Base Values) | G19: 2020-2030 | H19: 2030 | I19: 2030-2040 | J19: 2040 | K19: 2040-2045 | L19: 2045
A20: Volume of Emissions per 10 miles: | B20: 30 mpg (Diesel) | C20: The use of these household items would generate CO2 equivalent emissions the of this many Cubic ft
B21: 30 mpg (Diesel) | C21: =VLOOKUP(B20,'Daily HH CO2 w RPS'!A34:B45,2,FALSE) -> 115.40742 | D21: =$C$21 -> 115.40742 | E21: =$C$21 -> 115.40742 | F21: =$C$21 -> 115.40742 | G21: =$C$21 -> 115.40742 | H21: =$C$21 -> 115.40742 | I21: =$C$21 -> 115.40742 | J21: =$C$21 -> 115.40742 | K21: =$C$21 -> 115.40742 | L21: =$C$21 -> 115.40742
B22: 30 mpg (Diesel) | C22: Or a Ball of this many feet in diameter:
B23: 30 mpg (Diesel) | C23: =2*($C$21*3/4*1/3.14159)^(1/3) -> 6.0405779 | D23: =$C$23 -> 6.0405779 | E23: =$C$23 -> 6.0405779 | F23: =$C$23 -> 6.0405779 | G23: =$C$23 -> 6.0405779 | H23: =$C$23 -> 6.0405779 | I23: =$C$23 -> 6.0405779 | J23: =$C$23 -> 6.0405779 | K23: =$C$23 -> 6.0405779 | L23: =$C$23 -> 6.0405779
A27: EDITABLE CELLS
A29: For Reference:
A30: .25 ft Diameter | B30: ~ Baseball
A31: .8 ft Diamater | B31: ~ Basketball
A32: 1.4 ft Diameter | B32: ~ Extra Small Exercise Ball
A33: 2.8 ft Diameter | B33: ~Extra Large Exercise Ball

Sheet Daily HH CO2 w RPS
A1: RPS Standards & Resulting CO2e Emissions Volume | C1: Pre-Renewables | D1: 2010 | E1: 2015 | F1: (2021, Base Values) | G1: 2020-2030 | H1: 2030 | I1: 2030-2040 | J1: 2040 | K1: 2040-2045 | L1: 2045
A2: Percent Renewables | C2: 0 | D2: 10 | E2: 15 | F2: 19 | G2: 30 | H2: 40 | I2: 55 | J2: 70 | K2: 85 | L2: 100
A3: CO2 equivalent (metric tons) /MWh | C3: 0.9272265 | D3: 0.83450385 | E3: 0.78814252 | F3: 0.75127653 | G3: 0.64905855 | H3: 0.5563359 | I3: 0.41725192 | J3: 0.27816795 | K3: 0.13908397 | L3: 0
A4: Cubic ft/ MWh | C4: 16179.463 | D4: 14561.516 | E4: 13752.543 | F4: 13109.257 | G4: 11325.624 | H4: 9707.6776 | I4: 7280.7582 | J4: 4853.8388 | K4: 2426.9194 | L4: 0
A5: Cubic ft/ KWh | C5: 16.179463 | D5: 14.561516 | E5: 13.752543 | F5: 13.109257 | G5: 11.325624 | H5: 9.7076776 | I5: 7.2807582 | J5: 4.8538388 | K5: 2.4269194 | L5: 0
A6: Diameter of a Ball / KWH | C6: =2*(C5*3/4*1/3.14159)^(1/3) -> 3.1380169 | D6: =2*(D5*3/4*1/3.14159)^(1/3) -> 3.029722 | E6: =2*(E5*3/4*1/3.14159)^(1/3) -> 2.9725437 | F6: =2*(F5*3/4*1/3.14159)^(1/3) -> 2.925454 | G6: =2*(G5*3/4*1/3.14159)^(1/3) -> 2.7862578 | H6: =2*(H5*3/4*1/3.14159)^(1/3) -> 2.646706 | I6: =2*(I5*3/4*1/3.14159)^(1/3) -> 2.404692 | J6: =2*(J5*3/4*1/3.14159)^(1/3) -> 2.1006919 | ... L6: =2*(L5*3/4*1/3.14159)^(1/3) -> 0
A8: HouseHold Appliance Usage | B8: Daily KWH Usage | C8: The use of these household items would generate CO2 emissions the size of a ball with this diameter
A9: Ceiling Fan (12 hr.) | B9: 0.9 | C9: =$B9*C$6 -> 2.8242152 | D9: =$B9*D$6 -> 2.7267498 | E9: =$B9*E$6 -> 2.6752894 | F9: =$B9*F$6 -> 2.6329086 | G9: =$B9*G$6 -> 2.507632 | H9: =$B9*H$6 -> 2.3820354 | I9: =$B9*I$6 -> 2.1642228 | J9: =$B9*J$6 -> 1.8906227 | ... L9: =$B9*L$6 -> 0
A10: Refrigerator (24 hr.) | B10: 4.32 | C10: =$B10*C$6 -> 13.556233 | D10: =$B10*D$6 -> 13.088399 | E10: =$B10*E$6 -> 12.841389 | F10: =$B10*F$6 -> 12.637961 | G10: =$B10*G$6 -> 12.036634 | H10: =$B10*H$6 -> 11.43377 | I10: =$B10*I$6 -> 10.388269 | J10: =$B10*J$6 -> 9.0749891 | ... L10: =$B10*L$6 -> 0
A11: Oven (1 hr.) | B11: 3 | C11: =$B11*C$6 -> 9.4140507 | D11: =$B11*D$6 -> 9.089166 | E11: =$B11*E$6 -> 8.9176312 | F11: =$B11*F$6 -> 8.776362 | G11: =$B11*G$6 -> 8.3587733 | H11: =$B11*H$6 -> 7.9401179 | I11: =$B11*I$6 -> 7.2140759 | J11: =$B11*J$6 -> 6.3020757 | ... L11: =$B11*L$6 -> 0
A12: Slow Cooker (5 hr.) | B12: 1 | C12: =$B12*C$6 -> 3.1380169 | D12: =$B12*D$6 -> 3.029722 | E12: =$B12*E$6 -> 2.9725437 | F12: =$B12*F$6 -> 2.925454 | G12: =$B12*G$6 -> 2.7862578 | H12: =$B12*H$6 -> 2.646706 | I12: =$B12*I$6 -> 2.404692 | J12: =$B12*J$6 -> 2.1006919 | ... L12: =$B12*L$6 -> 0
A13: TV (3 hr.) | B13: 0.45 | C13: =$B13*C$6 -> 1.4121076 | D13: =$B13*D$6 -> 1.3633749 | E13: =$B13*E$6 -> 1.3376447 | F13: =$B13*F$6 -> 1.3164543 | G13: =$B13*G$6 -> 1.253816 | H13: =$B13*H$6 -> 1.1910177 | I13: =$B13*I$6 -> 1.0821114 | J13: =$B13*J$6 -> 0.94531136 | ... L13: =$B13*L$6 -> 0
A14: LED Lightbulb (5 hr.) | B14: 0.05 | C14: =$B14*C$6 -> 0.15690085 | D14: =$B14*D$6 -> 0.1514861 | E14: =$B14*E$6 -> 0.14862719 | F14: =$B14*F$6 -> 0.1462727 | G14: =$B14*G$6 -> 0.13931289 | H14: =$B14*H$6 -> 0.1323353 | I14: =$B14*I$6 -> 0.1202346 | J14: =$B14*J$6 -> 0.1050346 | ... L14: =$B14*L$6 -> 0
A15: Water Heater (3 hr.) | B15: 9 | C15: =$B15*C$6 -> 28.242152 | D15: =$B15*D$6 -> 27.267498 | E15: =$B15*E$6 -> 26.752894 | F15: =$B15*F$6 -> 26.329086 | G15: =$B15*G$6 -> 25.07632 | H15: =$B15*H$6 -> 23.820354 | I15: =$B15*I$6 -> 21.642228 | J15: =$B15*J$6 -> 18.906227 | ... L15: =$B15*L$6 -> 0
A16: Air Conditioner (5 hr.) | B16: 17.5 | C16: =$B16*C$6 -> 54.915296 | D16: =$B16*D$6 -> 53.020135 | E16: =$B16*E$6 -> 52.019515 | F16: =$B16*F$6 -> 51.195445 | G16: =$B16*G$6 -> 48.759511 | H16: =$B16*H$6 -> 46.317354 | I16: =$B16*I$6 -> 42.082109 | J16: =$B16*J$6 -> 36.762109 | ... L16: =$B16*L$6 -> 0
A17: Clothes Dryer (1 hr.) | B17: 3.4 | C17: =$B17*C$6 -> 10.669257 | D17: =$B17*D$6 -> 10.301055 | E17: =$B17*E$6 -> 10.106649 | F17: =$B17*F$6 -> 9.9465436 | G17: =$B17*G$6 -> 9.4732764 | H17: =$B17*H$6 -> 8.9988003 | I17: =$B17*I$6 -> 8.1759526 | J17: =$B17*J$6 -> 7.1423525 | ... L17: =$B17*L$6 -> 0
A18: Coffee Maker (.5 hr.) | B18: 0.75 | C18: =$B18*C$6 -> 2.3535127 | D18: =$B18*D$6 -> 2.2722915 | E18: =$B18*E$6 -> 2.2294078 | F18: =$B18*F$6 -> 2.1940905 | G18: =$B18*G$6 -> 2.0896933 | H18: =$B18*H$6 -> 1.9850295 | I18: =$B18*I$6 -> 1.803519 | J18: =$B18*J$6 -> 1.5755189 | ... L18: =$B18*L$6 -> 0
A19: Microwave (.25 hr.) | B19: 0.25 | C19: =$B19*C$6 -> 0.78450423 | D19: =$B19*D$6 -> 0.7574305 | E19: =$B19*E$6 -> 0.74313594 | F19: =$B19*F$6 -> 0.7313635 | G19: =$B19*G$6 -> 0.69656444 | H19: =$B19*H$6 -> 0.66167649 | I19: =$B19*I$6 -> 0.60117299 | J19: =$B19*J$6 -> 0.52517298 | ... L19: =$B19*L$6 -> 0
A20: Computer (1 hr.) | B20: 0.07 | C20: =$B20*C$6 -> 0.21966118 | D20: =$B20*D$6 -> 0.21208054 | E20: =$B20*E$6 -> 0.20807806 | F20: =$B20*F$6 -> 0.20478178 | G20: =$B20*G$6 -> 0.19503804 | H20: =$B20*H$6 -> 0.18526942 | I20: =$B20*I$6 -> 0.16832844 | J20: =$B20*J$6 -> 0.14704843 | ... L20: =$B20*L$6 -> 0
... A23: Router (24 hr.) | B23: 0.14 | C23: =$B23*C$6 -> 0.43932237 | D23: =$B23*D$6 -> 0.42416108 | E23: =$B23*E$6 -> 0.41615612 | F23: =$B23*F$6 -> 0.40956356 | G23: =$B23*G$6 -> 0.39007609 | H23: =$B23*H$6 -> 0.37053883 | I23: =$B23*I$6 -> 0.33665687 | J23: =$B23*J$6 -> 0.29409687 | ... L23: =$B23*L$6 -> 0
A27: Vehicle Calculations | B27: KWH/10 Miles | C27: The use of these household items would generate CO2 emissions the size of a ball with this diameter
A28: Tesla Kwh per 10 miles: | B28: 2 | C28: =$B$28*C5 -> 32.358925 | D28: =$B$28*D5 -> 29.123033 | E28: =$B$28*E5 -> 27.505086 | F28: =$B$28*F5 -> 26.218514 | G28: =$B$28*G5 -> 22.651248 | H28: =$B$28*H5 -> 19.415355 | I28: =$B$28*I5 -> 14.561516 | J28: =$B$28*J5 -> 9.7076776 | ... L28: =$B$28*L5 -> 0
A29: 80 Kwh for charge | B29: =B28 -> 2 | C29: =$B$29*C6 -> 6.2760338 | D29: =$B$29*D6 -> 6.059444 | E29: =$B$29*E6 -> 5.9450875 | F29: =$B$29*F6 -> 5.850908 | G29: =$B$29*G6 -> 5.5725155 | H29: =$B$29*H6 -> 5.2934119 | I29: =$B$29*I6 -> 4.8093839 | J29: =$B$29*J6 -> 4.2013838 | ... L29: =$B$29*L6 -> 0
A30: 340 Mile Range
A33: Vehicles, Emissions Per 10 Miles with 10% Ethanol | B33: Volume | C33: CO2 (tons)
A34: 10 mpg (Diesel) | B34: =C34*19234.57 -> 346.22226 | C34: 0.018
A35: 10 mpg (Hybrid) | B35: =C35*19234.57 -> 365.45683 | C35: 0.019
A36: 10 mpg (Ethanol 10) | B36: =C36*19234.57 -> 288.51855 | C36: 0.015
A37: 20 mpg (Diesel) | B37: =C37*19234.57 -> 173.11113 | C37: 0.009
A38: 20 mpg (Hybrid) | B38: =C38*19234.57 -> 173.11113 | C38: 0.009
A39: 20 mpg (Ethanol 10) | B39: =C39*19234.57 -> 153.87656 | C39: 0.008
A40: 30 mpg (Diesel) | B40: =C40*19234.57 -> 115.40742 | C40: 0.006
A41: 30 mpg (Hybrid) | B41: =C41*19234.57 -> 115.40742 | C41: 0.006
A42: 30 mpg (Ethanol 10) | B42: =C42*19234.57 -> 96.17285 | C42: 0.005
A43: 40 mpg (Diesel) | B43: =C43*19234.57 -> 76.93828 | C43: 0.004
A44: 40 mpg (Hybrid) | B44: =C44*19234.57 -> 96.17285 | C44: 0.005
A45: 40 mpg (Ethanol 10) | B45: =C45*19234.57 -> 76.93828 | C45: 0.004
A47: Conversions
A48: 1 mpg = 235.214583 l/100km
A49: 16.1 km = 10 mi
...

Sheet Sources
A1: Information | B1: Source
A2: Volume of CO2 | B2: Weight to Volume conversions for select substances and materials (aqua-calc.com)
A3: HI Plant Emissions | B3: https://www.epa.gov/egrid/download-data
A4: HI Renewable Portfolio Standards | B4: https://www.capitol.hawaii.gov/hrscurrent/Vol05_Ch0261-0319/HRS0269/HRS_0269-0092.htm
A5: Appliance Usage Estimates | B5: https://www.energybot.com/
A6: Vehicle Emissions | B6: Which form of transport has the smallest carbon footprint? - Our World in Data
A7: EV Charge KWh | B7: https://www.motorverso.com/how-many-kwh-to-charge-a-tesla/
A8: EV Charge Distance | B8: How Far Can a Tesla Go in One Charge? - The Motor Digest
A9: CO2e Vehicle Estimates | B9: Calculate the carbon footprint of your car trip– using the myclimate CO2 calculator | myclimate

Sheet Methods
A1: Assumptions:
A2: CO2 Volumes Are Derived from CO2 Equivalent Values
A3: All informaiton is based off of 100% Grid Usage
A4: Calculations are based off data from the year 2021
A5: Assumes that CO2e / MWh will be reduced at a constant rate according to 2021 values
A6: Assumes a constant electricity generation
A8: Method:
A9: Finding a conversion rate from KWh to Volume of CO2 emitted at different stages of the RPS
A10: 1. Found the Overall Statewide CO2 / MWh of generation
A11: 1a. Sum of all Emissions divided by sum of all generation
A12: 2. Found the Overall Statewide generation for ONLY emitting plants
A13: 2a. Filtered the data to exclude non-emitting sources
... A27: Left with: A ball of x diameter is released for specified usage of a given appliance
